# 7.了解结构化异常处理

在本章中，你将学习如何通过使用结构化异常处理来处理 C#代码中的运行时异常。你不仅会研究允许你处理这些事情的 C#关键字(`try`、`catch`、`throw`、`finally`、`when`)，而且你还会理解应用级和系统级异常之间的区别，以及`System.Exception`基类的作用。该讨论将引入构建自定义异常的主题，并最终快速浏览一些 Visual Studio 的以异常为中心的调试工具。

## 错误、错误和异常的颂歌

不管我们(有时是膨胀的)自我告诉我们什么，没有一个程序员是完美的。编写软件是一项复杂的任务，考虑到这种复杂性，即使是最好的软件也会出现各种问题，这是很常见的。有时问题是由糟糕的代码引起的(比如溢出数组的边界)。其他时候，问题是由伪造的用户输入引起的，这些用户输入在应用程序的代码库中没有考虑到(例如，分配给值`Chucky`的电话号码输入字段)。现在，不管问题的原因是什么，最终的结果都是应用程序不能像预期的那样工作。为了帮助构建即将到来的结构化异常处理的讨论，请允许我提供三个常用的以异常为中心的术语的定义。

*   bug:简单地说，就是程序员犯的错误。例如，假设您正在使用非托管 C++进行编程。如果您未能删除动态分配的内存，从而导致内存泄漏，那么您就有一个 bug。
*   用户错误:另一方面，用户错误通常是由运行您的应用程序的个人造成的，而不是由创建它的人造成的。例如，如果您无法在代码库中处理这种错误输入，最终用户在文本框中输入格式错误的字符串很可能会产生错误。
*   异常:异常通常被认为是运行时异常，在编写应用程序时很难(如果不是不可能的话)解释。可能的例外包括尝试连接到不再存在的数据库、打开损坏的 XML 文件或尝试联系当前脱机的计算机。在每一种情况下，程序员(或最终用户)对这些“异常”情况几乎没有控制力。

给定这些定义，应该很清楚。NET 结构化异常处理是一种处理运行时异常的技术。然而，即使对于那些你看不到的 bug 和用户错误，CLR 也经常会生成一个相应的异常来标识即将发生的问题。举几个例子。NET 基础类库定义了许多异常，比如`FormatException`、`IndexOutOfRangeException`、`FileNotFoundException`、`ArgumentOutOfRangeException`等等。

在。NET 命名法中，异常说明了 bug、伪造的用户输入和运行时错误，尽管程序员可能会将这些视为不同的问题。然而，在我走得太远之前，让我们形式化一下结构化异常处理的角色，看看它与传统的错误处理技术有什么不同。

Note

为了使本书中使用的代码示例尽可能简洁，我不会捕捉基类库中给定方法可能抛出的每个可能的异常。当然，在你的产品级项目中，你应该充分利用本章介绍的技术。

## 的作用。NET 异常处理

之前。NET 中，Windows 操作系统下的错误处理是一个混乱的技术大杂烩。许多程序员在给定应用程序的上下文中使用他们自己的错误处理逻辑。例如，开发团队可以定义一组表示已知错误条件的数字常量，并将它们用作方法返回值。举例来说，考虑下面的部分 C 代码:

`/* A very C-style error trapping mechanism. */`

`#define E_FILENOTFOUND 1000`

`int UseFileSystem()`

`{`

`// Assume something happens in this function`

`// that causes the following return value.`

`return E_FILENOTFOUND;`

`}`

`void main()`

`{`

`int retVal = UseFileSystem();`

`if(retVal == E_FILENOTFOUND)`

`printf("Cannot find file...");`

`}`

这种方法不太理想，因为常数`E_FILENOTFOUND`只不过是一个数值，对于如何处理这个问题来说远远不是一个有用的工具。理想情况下，您希望将错误的名称、描述性消息和其他关于该错误条件的有用信息打包到一个定义明确的包中(这正是结构化异常处理中发生的情况)。除了开发人员的特别技术之外，Windows API 还定义了数百个错误代码，这些错误代码来自于`#defines`、`HRESULT`以及简单布尔值(`bool`、`BOOL`、`VARIANT_BOOL`等等)的太多变体。

这些老技术的明显问题是严重缺乏对称性。每种方法都或多或少地适合于给定的技术、给定的语言，甚至可能是给定的项目。为了结束这种疯狂。NET 平台提供了发送和捕获运行时错误的标准技术:结构化异常处理。这种方法的美妙之处在于，开发人员现在有了一种统一的错误处理方法，这种方法对于所有面向。NET 平台。因此，C#程序员处理错误的方式在语法上类似于 VB 程序员，或者使用 C++/CLI 的 C++程序员。

额外的好处是，用于跨程序集和计算机边界抛出和捕获异常的语法是相同的。例如，如果您使用 C#来构建 Windows Communication Foundation(WCF)服务，您可以使用允许您在同一应用程序的方法之间引发异常的相同关键字，向远程调用方引发 SOAP 错误。

另一个好处是。NET exceptions 的一个特点是，异常不是接收一个神秘的数值，而是包含问题的可读描述的对象，以及首先触发异常的调用堆栈的详细快照。此外，您可以为最终用户提供帮助链接信息，将用户指向一个提供错误详细信息的 URL，以及自定义的程序员定义的数据。

### 的组成部分。NET 异常处理

使用结构化异常处理进行编程涉及到四个相关实体的使用。

*   表示异常详细信息的类类型
*   在正确情况下向调用方引发异常类实例的成员
*   调用者端调用易发生异常的成员的代码块
*   调用方的一段代码，如果发生异常，它将处理(或捕捉)异常

C#编程语言提供了五个关键字(`try`、`catch`、`throw`、`finally`和`when`，允许您抛出和处理异常。代表当前问题的对象是一个扩展了`System.Exception`的类(或其派生)。鉴于这一事实，让我们来看看这个以异常为中心的基类的作用。

### 系统。异常基类

所有异常最终都是从`System.Exception`基类派生的，而基类又是从`System.Object`派生的。这个类的关键是(注意，其中一些成员是虚拟的，因此可能被派生类重写):

`public class Exception : ISerializable, _Exception`

`{`

`// Public constructors`

`public Exception(string message, Exception innerException);`

`public Exception(string message);`

`public Exception();`

`...`

`// Methods`

`public virtual Exception GetBaseException();`

`public virtual void GetObjectData(SerializationInfo info,`

`StreamingContext context);`

`// Properties`

`public virtual IDictionary Data { get; }`

`public virtual string HelpLink { get; set; }`

`public Exception InnerException { get; }`

`public virtual string Message { get; }`

`public virtual string Source { get; set; }`

`public virtual string StackTrace { get; }`

`public MethodBase TargetSite { get; }`

`...`

`}`

正如您所看到的，由`System.Exception`定义的许多属性实际上是只读的。这是因为派生类型通常会为每个属性提供默认值。例如，`IndexOutOfRangeException`类型的默认消息是“索引超出了数组的界限。”

Note

`Exception`类实现了两个。网络接口。尽管您还没有检查接口(参见第 8 章[，但是请理解`_Exception i`接口允许由非托管代码库(如 COM 应用程序)处理. NET 异常，而 I `Serializable`接口允许跨边界(如机器边界)持久化异常对象。](08.html)

表 [7-1](#Tab1) 描述了`System.Exception`最重要的成员。

表 7-1。

Core Members of the System.Exception Type

<colgroup><col> <col></colgroup> 
| 系统。异常属性 | 生命的意义 |
| --- | --- |
| `Data` | 这个只读属性检索一组键/值对(由实现`IDictionary`的对象表示)，这些键/值对提供程序员定义的关于异常的附加信息。默认情况下，此集合为空。 |
| `HelpLink` | 此属性获取或设置详细描述错误的帮助文件或网站的 URL。 |
| `InnerException` | 此只读属性可用于获取导致当前异常发生的先前异常的信息。先前的异常通过将它们传递到最新异常的构造函数中来记录。 |
| `Message` | 此只读属性返回给定错误的文本描述。错误消息本身被设置为构造函数参数。 |
| `Source` | 此属性获取或设置引发当前异常的程序集或对象的名称。 |
| `StackTrace` | 此只读属性包含一个字符串，该字符串标识触发异常的调用序列。正如您可能猜到的那样，该属性在调试期间或者如果您想要将错误转储到外部错误日志中时非常有用。 |
| `TargetSite` | 这个只读属性返回一个`MethodBase`对象，该对象描述了关于抛出异常的方法的许多细节(调用`ToString()`将通过名称识别该方法)。 |

## 最简单的例子

为了说明结构化异常处理的有用性，您需要创建一个在正确(或者可以说异常)的情况下抛出异常的类。假设您已经创建了一个新的 C#控制台应用程序项目(名为 SimpleException ),它定义了由“has-a”关系关联的两个类类型(`Car`和`Radio`)。`Radio`类型定义了打开或关闭无线电电源的单一方法。

`class Radio`

`{`

`public void TurnOn(bool on)`

`{`

`if(on)`

`Console.WriteLine("Jamming...");`

`else`

`Console.WriteLine("Quiet time...");`

`}`

`}`

除了通过包含/委托利用`Radio`类之外，`Car`类(如下所示)的定义方式是，如果用户将`Car`对象加速到超过预定义的最大速度(使用名为`MaxSpeed`的常量成员变量指定)，其引擎就会爆炸，导致`Car`不可用(由名为`carIsDead`的私有`bool`成员变量捕获)。

除此之外，`Car`类型还有一些属性来表示当前速度和用户提供的“昵称”，以及各种构造函数来设置新的`Car`对象的状态。下面是完整的定义(带代码注释):

`class Car`

`{`

`// Constant for maximum speed.`

`public const int MaxSpeed = 100;`

`// Car properties.`

`public int CurrentSpeed {get; set;} = 0;`

`public string PetName {get; set;} = "";`

`// Is the car still operational?`

`private bool carIsDead;`

`// A car has-a radio.`

`private Radio theMusicBox = new Radio();`

`// Constructors.`

`public Car() {}`

`public Car(string name, int speed)`

`{`

`CurrentSpeed = speed;`

`PetName = name;`

`}`

`public void CrankTunes(bool state)`

`{`

`// Delegate request to inner object.`

`theMusicBox.TurnOn(state);`

`}`

`// See if Car has overheated.`

`public void Accelerate(int delta)`

`{`

`if (carIsDead)`

`Console.WriteLine("{0} is out of order...", PetName);`

`else`

`{`

`CurrentSpeed += delta;`

`if (CurrentSpeed > MaxSpeed)`

`{`

`Console.WriteLine("{0} has overheated!", PetName);`

`CurrentSpeed = 0;`

`carIsDead = true;`

`}`

`else`

`Console.WriteLine("=> CurrentSpeed = {0}", CurrentSpeed);`

`}`

`}`

`}`

现在，如果你实现一个`Main()`方法，强制一个`Car`对象超过预定义的最大速度(在`Car`类中设置为 100)，如下所示:

`static void Main(string[] args)`

`{`

`Console.WriteLine("***** Simple Exception Example *****");`

`Console.WriteLine("=> Creating a car and stepping on it!");`

`Car myCar = new Car("Zippy", 20);`

`myCar.CrankTunes(true);`

`for (int i = 0; i < 10; i++)`

`myCar.Accelerate(10);`

`Console.ReadLine();`

`}`

您将看到以下输出:

`***** Simple Exception Example *****`

`=> Creating a car and stepping on it!`

`Jamming...`

`=> CurrentSpeed = 30`

`=> CurrentSpeed = 40`

`=> CurrentSpeed = 50`

`=> CurrentSpeed = 60`

`=> CurrentSpeed = 70`

`=> CurrentSpeed = 80`

`=> CurrentSpeed = 90`

`=> CurrentSpeed = 100`

`Zippy has overheated!`

`Zippy is out of order...`

### 引发一般异常

现在您已经有了一个函数类，我将演示抛出异常的最简单方法。如果调用者试图加速`Car`超过其上限，当前的`Accelerate()`实现简单地显示一条错误消息。

如果用户试图在汽车遇到制造者后加速汽车，要改进这个方法抛出一个异常，您需要创建并配置一个新的`System.Exception`类实例，通过类构造函数设置只读`Message`属性的值。当你想把异常对象发送回调用者时，使用 C# `throw`关键字。下面是对`Accelerate()`方法的相关代码更新:

`// This time, throw an exception if the user speeds up beyond MaxSpeed.`

`public void Accelerate(int delta)`

`{`

`if (carIsDead)`

`Console.WriteLine("{0} is out of order...", PetName);`

`else`

`{`

`CurrentSpeed += delta;`

`if (CurrentSpeed >= MaxSpeed)`

`{`

`carIsDead = true;`

`CurrentSpeed = 0;`

`// Use the "throw" keyword to raise an exception.`

`throw new Exception(string.Format("{0} has overheated!", PetName));`

`}`

`else`

`Console.WriteLine("=> CurrentSpeed = {0}", CurrentSpeed);`

`}`

`}`

在研究调用者如何捕捉这个异常之前，让我们先来看几个有趣的地方。首先，当您抛出一个异常时，总是由您来决定到底是什么构成了问题中的错误，以及何时应该抛出一个异常。这里，你假设如果程序试图增加一个`Car`对象的速度超过最大值，应该抛出一个`System.Exception`对象来指示`Accelerate()`方法不能继续(这可能是也可能不是一个有效的假设；这将是您根据您正在创建的应用程序做出的判断。

或者，您可以实现`Accelerate()`来自动恢复，而不需要首先抛出异常。总的来说，只有在满足了更多的终止条件(例如，找不到必要的文件、无法连接到数据库等等)时，才应该抛出异常。确切地决定抛出异常的理由是一个您必须始终应对的设计问题。就目前的目的而言，假设要求一辆注定要失败的汽车加速会引发一个异常。

在任何情况下，如果您在此时使用`Main()`中之前的逻辑重新运行应用程序，异常最终会被抛出。如以下输出所示，不处理此错误的结果并不理想，因为您会收到一个详细的错误转储，然后程序会终止:

`***** Simple Exception Example *****`

`=> Creating a car and stepping on it!`

`Jamming...`

`=> CurrentSpeed = 30`

`=> CurrentSpeed = 40`

`=> CurrentSpeed = 50`

`=> CurrentSpeed = 60`

`=> CurrentSpeed = 70`

`=> CurrentSpeed = 80`

`=> CurrentSpeed = 90`

`Unhandled Exception: System.Exception: Zippy has overheated!`

`at SimpleException.Car.Accelerate(Int32 delta) in C:\MyBooks\C# Book (7th ed)`

`\Code\Chapter_7\SimpleException\Car.cs:line 62`

`at SimpleException.Program.Main(String[] args) in C:\MyBooks\C# Book (7th ed)`

`\Code\Chapter_7\SimpleException\Program.cs:line 20`

`Press any key to continue . . .`

### 捕捉异常

Note

对于那些即将到来的。请理解，类型成员不是用它们可能抛出的异常集(换句话说。NET 不支持检查异常)。不管是好是坏，您不需要处理给定成员抛出的每个异常。

因为`Accelerate()`方法现在抛出一个异常，调用者需要准备好处理这个异常，如果它发生的话。当你调用一个可能抛出异常的方法时，你使用了一个`try` / `catch`块。在您捕获异常对象之后，您能够调用异常对象的成员来提取问题的细节。

你如何处理这些数据很大程度上取决于你自己。您可能希望将此信息记录到报告文件中，将数据写入 Windows 事件日志，向系统管理员发送电子邮件，或者向最终用户显示问题。在这里，您只需将内容转储到控制台窗口:

`// Handle the thrown exception.`

`static void Main(string[] args)`

`{`

`Console.WriteLine("***** Simple Exception Example *****");`

`Console.WriteLine("=> Creating a car and stepping on it!");`

`Car myCar = new Car("Zippy", 20);`

`myCar.CrankTunes(true);`

`// Speed up past the car’s max speed to`

`// trigger the exception.`

`try`

`{`

`for(int i = 0; i < 10; i++)`

`myCar. Accelerate(10);`

`}`

`catch(Exception e)`

`{`

`Console.WriteLine("\n*** Error! ***");`

`Console.WriteLine("Method: {0}", e.TargetSite);`

`Console.WriteLine("Message: {0}", e.Message);`

`Console.WriteLine("Source: {0}", e.Source);`

`}`

`// The error has been handled, processing continues with the next statement.`

`Console.WriteLine("\n***** Out of exception logic *****");`

`Console.ReadLine();`

`}`

本质上，`try`块是一段可能在执行过程中抛出异常的语句。如果检测到异常，程序执行流程被发送到适当的`catch`模块。另一方面，如果`try`块中的代码没有触发异常，那么`catch`块将被完全跳过，一切正常。以下输出显示了该程序的测试运行:

`***** Simple Exception Example *****`

`=> Creating a car and stepping on it!`

`Jamming...`

`=> CurrentSpeed = 30`

`=> CurrentSpeed = 40`

`=> CurrentSpeed = 50`

`=> CurrentSpeed = 60`

`=> CurrentSpeed = 70`

`=> CurrentSpeed = 80`

`=> CurrentSpeed = 90`

`*** Error! ***`

`Method: Void Accelerate(Int32)`

`Message: Zippy has overheated!`

`Source: SimpleException`

`***** Out of exception logic *****`

正如你所看到的，在一个异常被处理后，应用程序可以从`catch`块后的点继续运行。在某些情况下，给定的异常可能非常关键，足以保证终止应用程序。然而，在很多情况下，异常处理程序中的逻辑将确保应用程序能够继续愉快地运行(尽管它的功能可能会稍微差一些，比如不能连接到远程数据源)。

## 配置异常的状态

目前，`Accelerate()`方法中配置的`System.Exception`对象只是建立一个暴露给`Message`属性的值(通过一个构造函数参数)。然而，如表 [7-1](#Tab1) 所示，`Exception`类还提供了许多附加成员(`TargetSite`、`StackTrace`、`HelpLink`和`Data`)，这些成员可用于进一步限定问题的性质。为了更好地展示当前的例子，让我们逐个分析这些成员的更多细节。

### TargetSite 属性

`System.Exception.` `TargetSite`属性允许您确定关于抛出给定异常的方法的各种细节。如前面的`Main()`方法所示，打印`TargetSite`的值将显示抛出异常的方法的返回类型、名称和参数类型。然而，`TargetSite`不仅仅返回一个香草味的字符串，而是一个强类型的`System.Reflection.MethodBase`对象。此类型可用于收集有关违规方法以及定义违规方法的类的大量详细信息。为了说明，假设先前的`catch`逻辑已经更新如下:

`static void Main(string[] args)`

`{`

`...`

`// TargetSite actually returns a MethodBase object.`

`catch(Exception e)`

`{`

`Console.WriteLine("\n*** Error! ***");`

`Console.WriteLine("Member name: {0}", e.TargetSite);`

`Console.WriteLine("Class defining member: {0}",`

`e.TargetSite.DeclaringType);`

`Console.WriteLine("Member type: {0}", e.TargetSite.MemberType);`

`Console.WriteLine("Message: {0}", e.Message);`

`Console.WriteLine("Source: {0}", e.Source);`

`}`

`Console.WriteLine("\n***** Out of exception logic *****");`

`Console.ReadLine();`

`}`

这一次，您使用`MethodBase.DeclaringType`属性来确定抛出错误的类的完全限定名(在本例中为`SimpleException.Car`)以及`MethodBase`对象的`MemberType`属性来标识引发该异常的成员类型(例如属性与方法)。在这种情况下，`catch`逻辑将显示以下内容:

`*** Error! ***`

`Member name: Void Accelerate(Int32)`

`Class defining member: SimpleException.Car`

`Member type: Method`

`Message: Zippy has overheated!`

`Source: SimpleException`

### StackTrace 属性

属性允许您识别导致异常的一系列调用。请注意，永远不要设置`StackTrace`的值，因为它是在创建异常时自动建立的。举例来说，假设你再次更新了你的`catch`逻辑。

`catch(Exception e)`

`{`

`...`

`Console.WriteLine("Stack: {0}", e.StackTrace);`

`}`

如果您要运行该程序，您会发现下面的堆栈跟踪被打印到控制台(当然，您的行号和文件路径可能不同):

`Stack: at SimpleException.Car.Accelerate(Int32 delta)`

`in c:\MyApps\SimpleException\car.cs:line 65 at SimpleException.Program.Main()`

`in c:\MyApps\SimpleException\Program.cs:line 21`

从`StackTrace`返回的`string`记录了导致抛出该异常的调用序列。注意这个`string`最下面的行号如何标识序列中的第一个调用，而最上面的行号标识违规成员的确切位置。显然，这些信息在给定应用程序的调试或日志记录过程中非常有用，因为您能够“跟踪”错误的来源。

### HelpLink 属性

虽然`TargetSite`和`StackTrace`属性允许程序员了解给定的异常，但是这些信息对最终用户没有什么用处。正如您已经看到的，`System.Exception.Message`属性可以用来获取可以显示给当前用户的可读信息。此外，`HelpLink`属性可以设置为将用户指向特定的 URL 或包含更多详细信息的标准 Windows 帮助文件。

默认情况下，由`HelpLink`属性管理的值是一个空字符串。如果您想用一个更有趣的值填充这个属性，您需要在抛出`System.Exception`对象之前这样做。下面是对`Car.Accelerate()`方法的相关更新:

`public void Accelerate(int delta)`

`{`

`if (carIsDead)`

`Console.WriteLine("{0} is out of order...", PetName);`

`else`

`{`

`CurrentSpeed += delta;`

`if (CurrentSpeed >= MaxSpeed)`

`{`

`carIsDead = true;`

`CurrentSpeed = 0;`

`// We need to call the HelpLink property, thus we need to`

`// create a local variable before throwing the Exception object.`

`Exception ex =`

`new Exception(string.Format("{0} has overheated!", PetName));`

`ex.HelpLink = "`[`http://www.CarsRUs.com`](http://www.carsrus.com/)T2】

`throw ex;`

`}`

`else`

`Console.WriteLine("=> CurrentSpeed = {0}", CurrentSpeed);`

`}`

`}`

现在可以更新`catch`逻辑来打印帮助链接信息，如下所示:

`catch(Exception e)`

`{`

`...`

`Console.WriteLine("Help Link: {0}", e.HelpLink);`

`}`

### 数据属性

`System.Exception`的`Data`属性允许你用相关的辅助信息(比如时间戳)填充一个异常对象。`Data`属性返回一个实现名为`IDictionary`的接口的对象，该接口在`System.Collections`名称空间中定义。第 8 章研究了基于接口编程的角色，以及`System.Collections`名称空间。目前，只需理解字典集合允许您创建一组使用特定键检索的值。观察`Car.Accelerate()`方法的下一次更新:

`public void Accelerate(int delta)`

`{`

`if (carIsDead)`

`Console.WriteLine("{0} is out of order...", PetName);`

`else`

`{`

`CurrentSpeed += delta;`

`if (CurrentSpeed >= MaxSpeed)`

`{`

`carIsDead = true;`

`CurrentSpeed = 0;`

`// We need to call the HelpLink property, thus we need`

`// to create a local variable before throwing the Exception object.`

`Exception ex =`

`new Exception(string.Format("{0} has overheated!", PetName));`

`ex.HelpLink = "`[`http://www.CarsRUs.com`](http://www.carsrus.com/)T2】

`// Stuff in custom data regarding the error.`

`ex.Data.Add("TimeStamp",`

`string.Format("The car exploded at {0}", DateTime.Now));`

`ex.Data.Add("Cause", "You have a lead foot.");`

`throw ex;`

`}`

`else`

`Console.WriteLine("=> CurrentSpeed = {0}", CurrentSpeed);`

`}`

`}`

为了成功地枚举键值对，您必须首先确保为`System.Collections`名称空间指定一个`using`指令，因为您将在包含实现您的`Main()`方法的类的文件中使用一个`DictionaryEntry`类型。

`using System.Collections;`

接下来，您需要更新`catch`逻辑来测试从`Data`属性返回的值不是`null`(默认值)。之后，使用`DictionaryEntry`类型的`Key`和`Value`属性将定制数据打印到控制台。

`catch (Exception e)`

`{`

`...`

`Console.WriteLine("\n-> Custom Data:");`

`foreach (DictionaryEntry de in e.Data)`

`Console.WriteLine("-> {0}: {1}", de.Key, de.Value);`

`}`

有了这个，这就是你看到的最终输出:

`***** Simple Exception Example *****`

`=> Creating a car and stepping on it!`

`Jamming...`

`=> CurrentSpeed = 30`

`=> CurrentSpeed = 40`

`=> CurrentSpeed = 50`

`=> CurrentSpeed = 60`

`=> CurrentSpeed = 70`

`=> CurrentSpeed = 80`

`=> CurrentSpeed = 90`

`*** Error! ***`

`Member name: Void Accelerate(Int32)`

`Class defining member: SimpleException.Car`

`Member type: Method`

`Message: Zippy has overheated!`

`Source: SimpleException`

`Stack: at SimpleException.Car.Accelerate(Int32 delta)`

`at SimpleException.Program.Main(String[] args)`

`Help Link:`[`http://www.CarsRUs.com`T3】](http://www.carsrus.com/)

`-> Custom Data:`

`-> TimeStamp: The car exploded at 9/12/2015 9:02:12 PM`

`-> Cause: You have a lead foot.`

`***** Out of exception logic *****`

`Data`属性是有用的，因为它允许你装入关于手边错误的定制信息，而不需要构建一个新的类类型来扩展`Exception`基类。尽管`Data`属性可能很有帮助，但是，它仍然很常见。NET 开发人员构建强类型异常类，这些类使用强类型属性处理自定义数据。

这种方法允许调用者捕捉一个特定的 e `xception`派生类型，而不必挖掘数据集合来获得额外的细节。为了理解如何做到这一点，您需要研究系统级异常和应用程序级异常之间的区别。

Source Code

SimpleException 项目包含在 [`Chapter 7`](07.html) 子目录中。

## 系统级异常(系统。系统异常)

那个。NET 基础类库定义了许多最终从`System.Exception`派生的类。例如，`System`名称空间定义了核心异常对象，如`ArgumentOutOfRangeException`、`IndexOutOfRangeException`、`StackOverflowException`等等。其他命名空间定义反映该命名空间行为的异常。例如，`System.Drawing.Printing`定义打印异常，`System.IO`定义基于输入/输出的异常，`System.Data`定义以数据库为中心的异常，等等。

引发的异常。NET 平台被(恰当地)称为系统异常。这些异常通常被认为是不可恢复的致命错误。系统异常直接从一个名为`System.SystemException`的基类派生而来，这个基类又从`System.Exception`派生而来(T1 又从`System.Object`派生而来)。

`public class SystemException : Exception`

`{`

`// Various constructors.`

`}`

假定`System.SystemException`类型除了一组自定义构造函数之外没有添加任何额外的功能，您可能会奇怪为什么`SystemException`首先会存在。简单地说，当一个异常类型从`System.SystemException`派生时，您能够确定。NET 运行库是引发异常的实体，而不是正在执行的应用程序的基本代码。您可以使用`is`关键字非常简单地验证这一点。

`// True! NullReferenceException is-a SystemException.`

`NullReferenceException nullRefEx = new NullReferenceException();`

`Console.WriteLine("NullReferenceException is-a SystemException? : {0}",`

`nullRefEx is SystemException);`

## 应用程序级异常(系统。应用程序异常)

鉴于这一切。NET 异常是类类型，您可以自由创建自己的特定于应用程序的异常。然而，因为`System.SystemException`基类表示从 CLR 抛出的异常，您可能会自然地认为您应该从`System.Exception`类型派生您的自定义异常。你可以这样做，但是你可以从`System.ApplicationException`类派生。

`public class ApplicationException : Exception`

`{`

`// Various constructors.`

`}`

和`SystemException`一样，`ApplicationException`除了一组构造函数之外，没有定义任何额外的成员。从功能上来说，`System.ApplicationException`的唯一目的是识别错误的来源。当您处理源自`System.ApplicationException`的异常时，您可以假设该异常是由正在执行的应用程序的代码库引发的，而不是由。NET 基类库或。NET 运行时引擎。

Note

实际上，很少。NET 开发人员构建扩展了`ApplicationException`的自定义异常。相反，更常见的是简单地子类化`System.Exception`；然而，这两种方法在技术上都是有效的。

### 构建自定义异常，取 1

虽然您总是可以抛出`System.Exception`的实例来表示运行时错误(如第一个示例所示)，但有时构建一个强类型异常来表示您当前问题的独特细节是有利的。例如，假设您想要构建一个定制的异常(名为`CarIsDeadException`)来表示加速一辆注定失败的汽车的错误。第一步是从`System.Exception` / `System.ApplicationException`派生一个新类(按照惯例，所有异常类都以`Exception`后缀结尾；事实上，这是一个. NET 最佳实践)。

Note

通常，所有定制的异常类都应该被定义为公共类(回想一下，非嵌套类型的默认访问修饰符是 internal)。原因是异常通常在程序集边界之外传递，因此调用代码基应该可以访问异常。

创建一个名为 CustomException 的新控制台应用程序项目，并使用项目添加现有项菜单选项将之前的`Car.cs`和`Radio.cs`文件复制到您的新项目中(为了清楚起见，请确保将定义`Car`和`Radio`类型的名称空间从`SimpleException`更改为`CustomException`)。接下来，添加以下类定义:

`// This custom exception describes the details of the car-is-dead condition.`

`// (Remember, you can also simply extend Exception.)`

`public class CarIsDeadException : ApplicationException`

`{}`

与任何类一样，您可以自由地包含任意数量的自定义成员，这些成员可以在调用逻辑的`catch`块中调用。您也可以自由地重写由父类定义的任何虚拟成员。例如，您可以通过覆盖虚拟的`Message`属性来实现`CarIsDeadException`。

同样，在抛出异常时，构造函数允许发送方传入时间戳和错误原因，而不是填充数据字典(通过`Data`属性)。最后，使用强类型属性可以获得时间戳数据和错误原因。

`public class CarIsDeadException : ApplicationException`

`{`

`private string messageDetails = String.Empty;`

`public DateTime ErrorTimeStamp {get; set;}`

`public string CauseOfError {get; set;}`

`public CarIsDeadException(){}`

`public CarIsDeadException(string message,`

`string cause, DateTime time)`

`{`

`messageDetails = message;`

`CauseOfError = cause;`

`ErrorTimeStamp = time;`

`}`

`// Override the Exception.Message property.`

`public override string Message`

`{`

`get`

`{`

`return string.Format("Car Error Message: {0}", messageDetails);`

`}`

`}`

`}`

这里，`CarIsDeadException`类维护一个私有字段(`messageDetails`)，表示关于当前异常的数据，可以使用自定义构造函数来设置。从`Accelerate()`方法中抛出这个异常非常简单。只需分配、配置并抛出一个`CarIsDeadException`类型，而不是一个`System.Exception`(注意，在这种情况下，您不再需要手动填充数据集合)。

`// Throw the custom CarIsDeadException.`

`public void Accelerate(int delta)`

`{`

`...`

`CarIsDeadException ex =`

`new CarIsDeadException (string.Format("{0} has overheated!", PetName),`

`"You have a lead foot", DateTime.Now);`

`ex.HelpLink = "`[`http://www.CarsRUs.com`](http://www.carsrus.com/)T2】

`throw ex;`

`...`

`}`

为了捕捉这个传入的异常，现在可以更新您的`catch`范围来捕捉一个特定的`CarIsDeadException`类型(然而，考虑到`CarIsDeadException`是一个`System.Exception`，捕捉一个`System.Exception`也是允许的)。

`static void Main(string[] args)`

`{`

`Console.WriteLine("***** Fun with Custom Exceptions *****\n");`

`Car myCar = new Car("Rusty", 90);`

`try`

`{`

`// Trip exception.`

`myCar.Accelerate(50);`

`}`

`catch (CarIsDeadException e)`

`{`

`Console.WriteLine(e.Message);`

`Console.WriteLine(e.ErrorTimeStamp);`

`Console.WriteLine(e.CauseOfError);`

`}`

`Console.ReadLine();`

`}`

因此，现在您已经理解了构建自定义异常的基本过程，您可能想知道何时需要这样做。通常，您只需要在错误与发出错误的类紧密绑定时创建自定义异常(例如，一个以文件为中心的自定义类，它抛出许多与文件相关的错误，一个`Car`类，它抛出许多与汽车相关的错误，一个数据访问对象，它抛出关于特定数据库表的错误，等等)。通过这样做，您为调用者提供了在描述性错误的基础上处理大量异常的能力。

### 构建自定义异常，取 2

当前的`CarIsDeadException`类型已经覆盖了虚拟的`System.Exception.Message`属性，以便配置一个定制的错误消息，并且已经提供了两个定制的属性来说明额外的数据位。然而，实际上，您不需要覆盖虚拟的`Message`属性，因为您可以简单地将传入的消息传递给父类的构造函数，如下所示:

`public class CarIsDeadException : ApplicationException`

`{`

`public DateTime ErrorTimeStamp { get; set; }`

`public string CauseOfError { get; set; }`

`public CarIsDeadException() { }`

`// Feed message to parent constructor.`

`public CarIsDeadException(string message, string cause, DateTime time)`

`:base(message)`

`{`

`CauseOfError = cause;`

`ErrorTimeStamp = time;`

`}`

`}`

注意，这次您没有定义一个字符串变量来表示消息，也没有覆盖`Message`属性。相反，您只是将参数传递给基类构造函数。使用这种设计，定制的异常类只不过是从`System.ApplicationException`派生的一个唯一命名的类(如果合适的话还有附加属性)，没有任何基类覆盖。

如果您的大多数(如果不是全部)自定义异常类都遵循这个简单的模式，请不要感到惊讶。很多时候，自定义异常的作用不一定是提供从基类继承的功能之外的附加功能，而是提供一个强名称类型，该类型清楚地标识错误的性质，因此客户端可以为不同类型的异常提供不同的处理程序逻辑。

### 构建自定义异常，取 3

如果您想构建一个真正整洁、适当的自定义异常类，您会希望确保您的类型符合。NET 最佳实践。具体来说，这要求您的自定义异常执行以下操作:

*   源自`Exception` / `ApplicationException`
*   用[ `System.Serializable` ]属性标记
*   定义默认构造函数
*   定义一个设置继承的`Message`属性的构造函数
*   定义一个处理“内部异常”的构造函数
*   定义一个构造函数来处理类型的序列化

根据你目前的背景。NET 中，您可能没有关于属性或对象序列化的经验，这很好。我将在后面讨论这些主题(参见[第 15 章](15.html)中关于属性的信息，以及[第 20 章](20.html)中关于序列化服务的细节)。然而，为了完成对构建自定义异常的检查，下面是对`CarIsDeadException`的最后一次迭代，它考虑了这些特殊构造函数中的每一个(其他自定义属性和构造函数将如“构建自定义异常，取 2”中的示例所示):

`[Serializable]`

`public class CarIsDeadException : ApplicationException`

`{`

`public CarIsDeadException() { }`

`public CarIsDeadException(string message) : base( message ) { }`

`public CarIsDeadException(string message,`

`System.Exception inner)`

`: base( message, inner ) { }`

`protected CarIsDeadException(`

`System.Runtime.Serialization.SerializationInfo info,`

`System.Runtime.Serialization.StreamingContext context)`

`: base( info, context ) { }`

`// Any additional custom properties, constructors and data members...`

`}`

假定构建自定义异常遵循。NET 最佳实践的区别仅仅在于它们的名称，您会很高兴地知道 Visual Studio 提供了一个名为 Exception 的代码片段模板(见图 [7-1](#Fig1) ),它将自动生成一个新的异常类，该类遵循。NET 最佳实践。(回想一下第 2 章中的[，代码片段可以通过键入其名称来激活，在本例中是`exception`，并按 Tab 键两次。)](02.html)

![A978-1-4842-1332-2_7_Fig1_HTML.jpg](A978-1-4842-1332-2_7_Fig1_HTML.jpg)

图 7-1。

The Exception code snippet template Source Code

CustomException 项目包含在 [`Chapter 7`](07.html) 子目录中。

## 处理多个异常

最简单的形式是，一个`try`块有一个`catch`块。然而，实际上，您经常会遇到这样的情况，即`try`块中的语句可能会触发许多可能的异常。创建一个名为 ProcessMultipleExceptions 的新 C#控制台应用程序项目；将先前 CustomException 示例中的`Car.cs`、`Radio.cs`和`CarIsDeadException.cs`文件添加到新项目中(通过项目➤添加现有项)；并相应地更新您的名称空间名称。

现在，更新`Car`的`Accelerate()`方法，如果传递一个无效参数(可以假设是任何小于零的值)，也抛出一个预定义的基类库`ArgumentOutOfRangeException`。注意，这个异常类的构造函数将有问题的参数的名称作为第一个`string`，后面跟着一条描述错误的消息。

`// Test for invalid argument before proceeding.`

`public void Accelerate(int delta)`

`{`

`if(delta < 0)`

`throw new`

`ArgumentOutOfRangeException("delta", "Speed must be greater than zero!");`

`...`

`}`

`catch`逻辑现在可以对每种类型的异常做出具体的响应。

`static void Main(string[] args)`

`{`

`Console.WriteLine("***** Handling Multiple Exceptions *****\n");`

`Car myCar = new Car("Rusty", 90);`

`try`

`{`

`// Trip Arg out of range exception.`

`myCar.Accelerate(-10);`

`}`

`catch (CarIsDeadException e)`

`{`

`Console.WriteLine(e.Message);`

`}`

`catch (ArgumentOutOfRangeException e)`

`{`

`Console.WriteLine(e.Message);`

`}`

`Console.ReadLine();`

`}`

当您创作多个`catch`块时，您必须意识到当一个异常被抛出时，它将被第一个适当的 catch 处理。为了准确地说明“第一个适当的”catch 的含义，假设您用一个额外的`catch`作用域改进了前面的逻辑，该作用域试图通过捕获一个一般的`System.Exception`来处理`CarIsDeadException`和`ArgumentOutOfRangeException`之外的所有异常，如下所示:

`// This code will not compile!`

`static void Main(string[] args)`

`{`

`Console.WriteLine("***** Handling Multiple Exceptions *****\n");`

`Car myCar = new Car("Rusty", 90);`

`try`

`{`

`// Trigger an argument out of range exception.`

`myCar.Accelerate(-10);`

`}`

`catch(Exception e)`

`{`

`// Process all other exceptions?`

`Console.WriteLine(e.Message);`

`}`

`catch (CarIsDeadException e)`

`{`

`Console.WriteLine(e.Message);`

`}`

`catch (ArgumentOutOfRangeException e)`

`{`

`Console.WriteLine(e.Message);`

`}`

`Console.ReadLine();`

`}`

这种异常处理逻辑会产生编译时错误。问题是因为第一个`catch`块可以处理从`System.Exception`派生的任何东西(给定“是-a”关系)，包括`CarIsDeadException`和`ArgumentOutOfRangeException`类型。因此，最后两个`catch`区块是不可及的！

要记住的经验法则是确保你的`catch`块的结构是这样的，第一个 catch 是最具体的异常(即异常类型继承链中最具派生性的类型)，最后一个`catch`是最一般的异常(即给定异常继承链的基类，在这里是`System.Exception`)。

因此，如果你想定义一个`catch`块来处理任何超过`CarIsDeadException`和`ArgumentOutOfRangeException`的错误，你可以写如下:

`// This code compiles just fine.`

`static void Main(string[] args)`

`{`

`Console.WriteLine("***** Handling Multiple Exceptions *****\n");`

`Car myCar = new Car("Rusty", 90);`

`try`

`{`

`// Trigger an argument out of range exception.`

`myCar.Accelerate(-10);`

`}`

`catch (CarIsDeadException e)`

`{`

`Console.WriteLine(e.Message);`

`}`

`catch (ArgumentOutOfRangeException e)`

`{`

`Console.WriteLine(e.Message);`

`}`

`// This will catch any other exception`

`// beyond CarIsDeadException or`

`// ArgumentOutOfRangeException.`

`catch (Exception e)`

`{`

`Console.WriteLine(e.Message);`

`}`

`Console.ReadLine();`

`}`

Note

只要有可能，总是支持捕获特定的异常类，而不是一般的`System.Exception`。虽然它可能在短期内使生活变得简单(你可能会想，“啊！这抓住了我不关心的所有其他事情。”)，从长远来看，您可能会以奇怪的运行时崩溃告终，因为您的代码中没有直接处理更严重的错误。记住，处理`System.Exception`的最后一个`catch`块实际上非常通用。

### 通用 catch 语句

C#还支持“通用”`catch`作用域，该作用域不显式接收由给定成员引发的异常对象。

`// A generic catch.`

`static void Main(string[] args)`

`{`

`Console.WriteLine("***** Handling Multiple Exceptions *****\n");`

`Car myCar = new Car("Rusty", 90);`

`try`

`{`

`myCar.Accelerate(90);`

`}`

`catch`

`{`

`Console.WriteLine("Something bad happened...");`

`}`

`Console.ReadLine();`

`}`

显然，这不是处理异常的最有用的方法，因为您无法获得关于所发生错误的有意义的数据(例如方法名、调用堆栈或自定义消息)。尽管如此，C#确实允许这样的构造，当您希望以一种通用的方式处理所有错误时，这是很有帮助的。

### 再次引发异常

当您捕捉到一个异常时，允许一个`try`块中的逻辑在调用栈中将该异常重新抛出给前一个调用者。为此，只需在`catch`块中使用`throw`关键字。这将异常沿调用逻辑链向上传递，如果您的`catch`块只能部分处理手边的错误，这将很有帮助。

`// Passing the buck.`

`static void Main(string[] args)`

`{`

`...`

`try`

`{`

`// Speed up car logic...`

`}`

`catch(CarIsDeadException e)`

`{`

`// Do any partial processing of this error and pass the buck.`

`throw;`

`}`

`...`

`}`

请注意，在这个示例代码中，`CarIsDeadException`的最终接收者是 CLR，因为它是再次抛出异常的`Main()`方法。因此，您的最终用户会看到系统提供的错误对话框。通常，您只会将部分处理的异常重新引发给有能力更优雅地处理传入异常的调用方。

还要注意，您没有显式地重新抛出`CarIsDeadException`对象，而是使用了不带参数的`throw`关键字。您没有创建新的异常对象；您只是重新抛出原始异常对象(及其所有原始信息)。这样做可以保留原始目标的上下文。

### 内部异常

正如您可能会怀疑的那样，在您处理另一个异常时触发一个异常是完全可能的。例如，假设您正在一个特定的`catch`范围内处理一个`CarIsDeadException`，在这个过程中，您试图将堆栈跟踪记录到 C: drive 上一个名为`carErrors.txt`的文件中(您必须指定您正在使用`System.IO`名称空间来访问这些以 I/O 为中心的类型)。

`catch(CarIsDeadException e)`

`{`

`// Attempt to open a file named carErrors.txt on the C drive.`

`FileStream fs = File.Open(@"C:\carErrors.txt", FileMode.Open);`

`...`

`}`

现在，如果指定的文件不在您的 C:驱动器上，调用`File.Open()`会导致一个`FileNotFoundException`！在本书的后面，您将了解关于`System.IO`名称空间的所有内容，在这里您将发现如何在试图打开文件之前，以编程方式确定文件是否存在于硬盘上(从而完全避免异常)。然而，为了保持对异常主题的关注，假设已经引发了异常。

当您在处理另一个异常时遇到另一个异常时，最佳实践表明，您应该将新的异常对象作为“内部异常”记录在与初始异常类型相同的新对象中。(真是拗口！)您需要为正在处理的异常分配一个新对象的原因是，记录内部异常的唯一方法是通过构造函数参数。考虑以下代码:

`catch (CarIsDeadException e)`

`{`

`try`

`{`

`FileStream fs = File.Open(@"C:\carErrors.txt", FileMode.Open);`

`...`

`}`

`catch (Exception e2)`

`{`

`// Throw an exception that records the new exception,`

`// as well as the message of the first exception.`

`throw new CarIsDeadException(e.Message, e2);`

`}`

`}`

注意，在这种情况下，我将`FileNotFoundException`对象作为第二个参数传递给了`CarIsDeadException`构造函数。在配置好这个新对象之后，将它在调用栈中向上抛出给下一个调用者，在本例中就是`Main()`方法。

假设在`Main()`之后没有“下一个调用者”来捕捉异常，您将再次看到一个错误对话框。与再次引发异常的行为非常相似，记录内部异常通常只有在调用者有能力首先捕获异常时才有用。如果是这种情况，调用者的`catch`逻辑可以使用`InnerException`属性提取内部异常对象的细节。

### 最终块

一个`try` / `catch`作用域也可以定义一个可选的`finally`块。`finally`块的目的是确保一组代码语句将始终执行，无论是否有异常(任何类型)。举例来说，假设您希望在退出`Main()`之前总是关闭汽车的无线电，而不管任何已处理的异常。

`static void Main(string[] args)`

`{`

`Console.WriteLine("***** Handling Multiple Exceptions *****\n");`

`Car myCar = new Car("Rusty", 90);`

`myCar.CrankTunes(true);`

`try`

`{`

`// Speed up car logic.`

`}`

`catch(CarIsDeadException e)`

`{`

`// Process CarIsDeadException.`

`}`

`catch(ArgumentOutOfRangeException e)`

`{`

`// Process ArgumentOutOfRangeException.`

`}`

`catch(Exception e)`

`{`

`// Process any other Exception.`

`}`

`finally`

`{`

`// This will always occur. Exception or not.`

`myCar.CrankTunes(false);`

`}`

`Console.ReadLine();`

`}`

如果您没有包含`finally`块，无线电将不会在遇到异常时关闭(这可能有问题，也可能没有问题)。在一个更真实的场景中，当您需要处理对象、关闭文件或从数据库中分离(或其他)时，一个`finally`块确保了一个适当清理的位置。

### 异常过滤器

C#的当前版本引入了一个新的(完全可选的)子句，可以通过关键字`when`放在`catch`范围内。当您添加这个子句时，您有能力确保只有当代码中的某些条件为真时，才会执行`catch`块中的语句。该表达式的计算结果必须为布尔值(true 或 false ),并且可以通过在 when 定义本身中使用简单的代码语句或在代码中调用其他方法来获得。简而言之，这种方法允许您向异常逻辑添加“过滤器”。

首先，假设您已经向`CarIsDeadException`添加了一些自定义属性。

`public class CarIsDeadException : ApplicationException`

`{`

`...`

`// Custom members for our exception.`

`public DateTime ErrorTimeStamp { get; set; }`

`public string CauseOfError { get; set; }`

`public CarIsDeadException(string message,`

`string cause, DateTime time)`

`: base(message)`

`{`

`CauseOfError = cause;`

`ErrorTimeStamp = time;`

`}`

`}`

还假设`Accelerate()`方法在抛出错误时使用这个新的构造函数。

`CarIsDeadException ex =`

`new CarIsDeadException(string.Format("{0} has overheated!", PetName),`

`"You have a lead foot", DateTime.Now);`

现在，考虑下面修改过的异常逻辑。这里，我在`CarIsDeadException`处理程序中添加了一个 when 子句，以确保`catch`块永远不会在星期五执行(这是一个虚构的例子，但是谁会希望他们的汽车在周末抛锚呢？).注意，`when`子句中的单个布尔语句必须用括号括起来(还要注意，您现在在这个范围内打印出一条新消息，只有当条件为`true`时才会输出)。

`catch (CarIsDeadException e) when (e.ErrorTimeStamp.DayOfWeek != DayOfWeek.Friday)`

`{`

`// This new line will only print if the when clause evaluates to true.`

`Console.WriteLine("Catching car is dead!");`

`Console.WriteLine(e.Message);`

`}`

虽然在任何情况下，对于给定的错误，您都有可能只有一个`catch`子句，但是正如您所看到的，新的`when`关键字允许您在响应运行时错误时获得更细粒度的响应。

## 使用 Visual Studio 调试未处理的异常

请注意，Visual Studio 提供了许多工具来帮助您调试未处理的自定义异常。同样，假设您已经将一个`Car`对象的速度提高到超过最大值，但是这次没有麻烦将您的调用包装在一个`try`块中。

`Car myCar = new Car("Rusty", 90);`

`myCar.Accelerate(2000);`

如果在 Visual Studio 中启动调试会话(使用“调试”➤“启动调试”菜单选项)，Visual Studio 会在引发未捕获的异常时自动中断。更好的是，你会看到一个窗口(见图 [7-2](#Fig2) )显示`Message`属性的值。

![A978-1-4842-1332-2_7_Fig2_HTML.jpg](A978-1-4842-1332-2_7_Fig2_HTML.jpg)

图 7-2。

Debugging unhandled custom exceptions with Visual Studio Note

如果未能处理由。NET 基类库，Visual Studio 调试器在调用有问题的方法的语句处中断。

如果您点击查看详细信息链接，您将找到关于对象状态的详细信息(参见图 [7-3](#Fig3) )。

![A978-1-4842-1332-2_7_Fig3_HTML.jpg](A978-1-4842-1332-2_7_Fig3_HTML.jpg)

图 7-3。

Viewing exception details Source Code

ProcessMultipleExceptions 项目包含在 [`Chapter 7`](07.html) 子目录中。

## 摘要

在本章中，您研究了结构化异常处理的作用。当一个方法需要向调用者发送一个错误对象时，它会通过 C# `throw`关键字分配、配置并抛出一个特定的`System.Exception`派生类型。调用者能够使用 C# `catch`关键字和可选的`finally`作用域来处理任何可能的异常。如图所示，C# 6.0 现在支持使用可选的`when`关键字创建异常过滤器。

当您创建自己的定制异常时，您最终会创建一个从`System.ApplicationException`派生的类类型，这表示一个从当前执行的应用程序抛出的异常。相比之下，从`System.SystemException`派生的错误对象表示由 CLR 抛出的严重(和致命)错误。最后但同样重要的是，本章说明了 Visual Studio 中可用于创建自定义异常的各种工具(根据。NET 最佳实践)以及调试异常。